Workbook
Name Slicer_Business_Unit: #N/A
Name Slicer_Category: #N/A
Name Slicer_Department: #N/A
Name Slicer_Months__Date: #N/A

Sheet RAW DATA
A1: Transaction ID | B1: Date | C1: Department | D1: Region | E1: Business Unit | F1: Category | G1: Type | H1: Budget Amount | I1: Actual Amount
A2: HTH00001 | B2: 45658 | C2: Emergency | D2: Kerala | E2: Emergency Services | F2: Consultation Services | G2: Revenue | H2: 234633 | I2: 204200
A3: HTH00002 | B3: 45658 | C3: General Medicine | D3: Kerala | E3: Outpatient Services | F3: Administrative Costs | G3: Expense | H3: 29489 | I3: 26100
A4: HTH00003 | B4: 45658 | C4: Neurology | D4: Kerala | E4: Inpatient Services | F4: Treatment Services | G4: Revenue | H4: 59413 | I4: 64500
A5: HTH00004 | B5: 45658 | C5: Orthopedics | D5: Kerala | E5: Inpatient Services | F5: Pharmacy Services | G5: Revenue | H5: 172361 | I5: 214700
A6: HTH00005 | B6: 45658 | C6: Orthopedics | D6: Kerala | E6: Inpatient Services | F6: Pharmacy Services | G6: Revenue | H6: 238392 | I6: 237000
A7: HTH00006 | B7: 45658 | C7: Orthopedics | D7: Kerala | E7: Inpatient Services | F7: Pharmacy Services | G7: Revenue | H7: 99794 | I7: 111400
A8: HTH00007 | B8: 45658 | C8: Orthopedics | D8: Kerala | E8: Inpatient Services | F8: Emergency Services | G8: Revenue | H8: 110782 | I8: 121700
A9: HTH00008 | B9: 45658 | C9: Pediatrics | D9: Kerala | E9: Outpatient Services | F9: Administrative Costs | G9: Expense | H9: 82243 | I9: 78000
A10: HTH00009 | B10: 45658 | C10: Pediatrics | D10: Kerala | E10: Outpatient Services | F10: Medicines & Supplies | G10: Expense | H10: 67385 | I10: 71900
A11: HTH00010 | B11: 45659 | C11: Emergency | D11: Kerala | E11: Emergency Services | F11: Emergency Services | G11: Revenue | H11: 138538 | I11: 127300
A12: HTH00011 | B12: 45659 | C12: Laboratory | D12: Kerala | E12: Diagnostic Services | F12: Medicines & Supplies | G12: Expense | H12: 112373 | I12: 107600
A13: HTH00012 | B13: 45659 | C13: Neurology | D13: Kerala | E13: Inpatient Services | F13: Medical Supplies | G13: Expense | H13: 117635 | I13: 96600
... A2501: HTH02500 | B2501: 46022 | C2501: Pediatrics | D2501: Kerala | E2501: Outpatient Services | F2501: Diagnostic Services | G2501: Revenue | H2501: 129402 | I2501: 141300

Sheet CLEANED DATA
A1: Transaction ID | B1: Date | C1: Department | D1: Region | E1: Business Unit | F1: Category | G1: Type | H1: Budget Amount | I1: Actual Amount
A2: HTH00001 | B2: 45658 | C2: Emergency | D2: Kerala | E2: Emergency Services | F2: Consultation Services | G2: Revenue | H2: 234633 | I2: 204200
A3: HTH00002 | B3: 45658 | C3: General Medicine | D3: Kerala | E3: Outpatient Services | F3: Administrative Costs | G3: Expense | H3: 29489 | I3: 26100
A4: HTH00003 | B4: 45658 | C4: Neurology | D4: Kerala | E4: Inpatient Services | F4: Treatment Services | G4: Revenue | H4: 59413 | I4: 64500
A5: HTH00004 | B5: 45658 | C5: Orthopedics | D5: Kerala | E5: Inpatient Services | F5: Pharmacy Services | G5: Revenue | H5: 172361 | I5: 214700
A6: HTH00005 | B6: 45658 | C6: Orthopedics | D6: Kerala | E6: Inpatient Services | F6: Pharmacy Services | G6: Revenue | H6: 238392 | I6: 237000
A7: HTH00006 | B7: 45658 | C7: Orthopedics | D7: Kerala | E7: Inpatient Services | F7: Pharmacy Services | G7: Revenue | H7: 99794 | I7: 111400
A8: HTH00007 | B8: 45658 | C8: Orthopedics | D8: Kerala | E8: Inpatient Services | F8: Emergency Services | G8: Revenue | H8: 110782 | I8: 121700
A9: HTH00008 | B9: 45658 | C9: Pediatrics | D9: Kerala | E9: Outpatient Services | F9: Administrative Costs | G9: Expense | H9: 82243 | I9: 78000
A10: HTH00009 | B10: 45658 | C10: Pediatrics | D10: Kerala | E10: Outpatient Services | F10: Medicines & Supplies | G10: Expense | H10: 67385 | I10: 71900
A11: HTH00010 | B11: 45659 | C11: Emergency | D11: Kerala | E11: Emergency Services | F11: Emergency Services | G11: Revenue | H11: 138538 | I11: 127300
A12: HTH00011 | B12: 45659 | C12: Laboratory | D12: Kerala | E12: Diagnostic Services | F12: Medicines & Supplies | G12: Expense | H12: 112373 | I12: 107600
A13: HTH00012 | B13: 45659 | C13: Neurology | D13: Kerala | E13: Inpatient Services | F13: Medical Supplies | G13: Expense | H13: 117635 | I13: 96600
... A2501: HTH02500 | B2501: 46022 | C2501: Pediatrics | D2501: Kerala | E2501: Outpatient Services | F2501: Diagnostic Services | G2501: Revenue | H2501: 129402 | I2501: 141300

Sheet DEPARTMENT-FINANCIAL ANALYSIS
A1: DEPARTMENT-WISE FINANCIAL ANALYSIS
A2: Formula-driven from CLEANED DATA
A3: DEPARTMENT | B3: Revenue Budget | C3: Revenue Actual | D3: Revenue Variance | E3: variance | F3: favorable/unfavorable | G3: Expense Budget | H3: Expense Actual | I3: Expense variance | J3: variance | K3: favorable/unfavorable
A4: Cardiology | B4: {=SUMIFS('CLEANED DATA'!$H:$H,'CLEANED DATA'!$C:$C,'DEPARTMENT-FINANCIAL ANALYSIS'!A4:A11,'CLEANED DATA'!$G:$G,"Revenue")} -> 26741056 | C4: {=SUMIFS('CLEANED DATA'!$I:$I,'CLEANED DATA'!$C:$C,'DEPARTMENT-FINANCIAL ANALYSIS'!A4:A11,'CLEANED DATA'!$G:$G,"Revenue")} -> 26825000 | D4: =C4-B4 -> 83944 | E4: =(C4-B4)/B4 -> 0.003139143 | F4: =IF(C4>B4,"Favorable","Unfavorable") -> Favorable | G4: {=SUMIFS('CLEANED DATA'!$H:$H,'CLEANED DATA'!$C:$C,'DEPARTMENT-FINANCIAL ANALYSIS'!A4:A11,'CLEANED DATA'!$G:$G,"Expense")} -> 11084849 | H4: {=SUMIFS('CLEANED DATA'!$I:$I,'CLEANED DATA'!$C:$C,'DEPARTMENT-FINANCIAL ANALYSIS'!A4:A11,'CLEANED DATA'!$G:$G,"Expense")} -> 10939000 | I4: =G4-H4 -> 145849 | J4: =I4/G4 -> 0.013157509 | K4: =IF(G4>H4,"Favorable","Unfavorable") -> Favorable
A5: Emergency | B5: 16417217 | C5: 16312100 | D5: =C5-B5 -> -105117 | E5: =(C5-B5)/B5 -> -0.0064028513 | F5: =IF(C5>B5,"Favorable","Unfavorable") -> Unfavorable | G5: 9326324 | H5: 9358200 | I5: =G5-H5 -> -31876 | J5: =I5/G5 -> -0.0034178525 | K5: =IF(G5>H5,"Favorable","Unfavorable") -> Unfavorable
A6: General Medicine | B6: 23837386 | C6: 23845700 | D6: =C6-B6 -> 8314 | E6: =(C6-B6)/B6 -> 0.00034877985 | F6: =IF(C6>B6,"Favorable","Unfavorable") -> Favorable | G6: 13025079 | H6: 13121000 | I6: =G6-H6 -> -95921 | J6: =I6/G6 -> -0.0073643315 | K6: =IF(G6>H6,"Favorable","Unfavorable") -> Unfavorable
A7: Laboratory | B7: 20399434 | C7: 20357000 | D7: =C7-B7 -> -42434 | E7: =(C7-B7)/B7 -> -0.0020801558 | F7: =IF(C7>B7,"Favorable","Unfavorable") -> Unfavorable | G7: 9027509 | H7: 8914000 | I7: =G7-H7 -> 113509 | J7: =I7/G7 -> 0.012573679 | K7: =IF(G7>H7,"Favorable","Unfavorable") -> Favorable
A8: Neurology | B8: 23418063 | C8: 23640600 | D8: =C8-B8 -> 222537 | E8: =(C8-B8)/B8 -> 0.0095027928 | F8: =IF(C8>B8,"Favorable","Unfavorable") -> Favorable | G8: 11213837 | H8: 11174500 | I8: =G8-H8 -> 39337 | J8: =I8/G8 -> 0.0035078983 | K8: =IF(G8>H8,"Favorable","Unfavorable") -> Favorable
A9: Orthopedics | B9: 22281731 | C9: 21791300 | D9: =C9-B9 -> -490431 | E9: =(C9-B9)/B9 -> -0.022010453 | F9: =IF(C9>B9,"Favorable","Unfavorable") -> Unfavorable | G9: 11413641 | H9: 11500600 | I9: =G9-H9 -> -86959 | J9: =I9/G9 -> -0.0076188659 | K9: =IF(G9>H9,"Favorable","Unfavorable") -> Unfavorable
A10: Pediatrics | B10: 16659198 | C10: 16483400 | D10: =C10-B10 -> -175798 | E10: =(C10-B10)/B10 -> -0.010552609 | F10: =IF(C10>B10,"Favorable","Unfavorable") -> Unfavorable | G10: 10824005 | H10: 10735000 | I10: =G10-H10 -> 89005 | J10: =I10/G10 -> 0.0082229267 | K10: =IF(G10>H10,"Favorable","Unfavorable") -> Favorable
A11: Radiology | B11: 17664878 | C11: 17480000 | D11: =C11-B11 -> -184878 | E11: =(C11-B11)/B11 -> -0.010465852 | F11: =IF(C11>B11,"Favorable","Unfavorable") -> Unfavorable | G11: 9363408 | H11: 9430200 | I11: =G11-H11 -> -66792 | J11: =I11/G11 -> -0.0071333002 | K11: =IF(G11>H11,"Favorable","Unfavorable") -> Unfavorable
A14: Favorability logic
A15: Revenue: Actual above Budget = Favorable
A16: Expense: Actual below Budget = Favorable

Sheet CATEGORY-FINANCIAL ANALYSIS
A1: CATEGORY-WISE FINANCIAL ANALYSIS
A2: Formula-driven from CLEANED DATA
A3: CATEGORY-WISE FINANCIAL ANALYSIS | B3: Revenue Budget | C3: Revenue Actual | D3: Revenue Variance | E3: variance | F3: favorable/unfavorable
A4: Consultation Services | B4: {=SUMIFS('CLEANED DATA'!$H:$H,'CLEANED DATA'!$F:$F,'CATEGORY-FINANCIAL ANALYSIS'!A4:A9,'CLEANED DATA'!$G:$G,"Revenue")} -> 27015191 | C4: {=SUMIFS('CLEANED DATA'!$I:$I,'CLEANED DATA'!$F:$F,'CATEGORY-FINANCIAL ANALYSIS'!A4:A9,'CLEANED DATA'!$G:$G,"Revenue")} -> 26643300 | D4: =C4-B4 -> -371891 | E4: =D4/B4 -> -0.013765996 | F4: =IF(C4>B4,"Favorable","Unfavorable") -> Unfavorable
A5: Diagnostic Services | B5: 28450338 | C5: 28248500 | D5: =C5-B5 -> -201838 | E5: =D5/B5 -> -0.0070943973 | F5: =IF(C5>B5,"Favorable","Unfavorable") -> Unfavorable
A6: Emergency Services | B6: 26771145 | C6: 26666800 | D6: =C6-B6 -> -104345 | E6: =D6/B6 -> -0.0038976667 | F6: =IF(C6>B6,"Favorable","Unfavorable") -> Unfavorable
A7: Pharmacy Services | B7: 27653613 | C7: 27624500 | D7: =C7-B7 -> -29113 | E7: =D7/B7 -> -0.0010527738 | F7: =IF(C7>B7,"Favorable","Unfavorable") -> Unfavorable
A8: Surgical Services | B8: 27681806 | C8: 27397000 | D8: =C8-B8 -> -284806 | E8: =D8/B8 -> -0.010288563 | F8: =IF(C8>B8,"Favorable","Unfavorable") -> Unfavorable
A9: Treatment Services | B9: 29846870 | C9: 30155000 | D9: =C9-B9 -> 308130 | E9: =D9/B9 -> 0.010323696 | F9: =IF(C9>B9,"Favorable","Unfavorable") -> Favorable
A13: CATEGORY-WISE FINANCIAL ANALYSIS
A15: CATEGORY-WISE FINANCIAL ANALYSIS | B15: ExpenseBudget | C15: Expense Actual | D15: Expense Variance | E15: variance | F15: favorable/unfavorable
A16: Administrative Costs | B16: {=SUMIFS('CLEANED DATA'!$H:$H,'CLEANED DATA'!$F:$F,'CATEGORY-FINANCIAL ANALYSIS'!A16:A21,'CLEANED DATA'!$G:$G,"Expense")} -> 14030572 | C16: {=SUMIFS('CLEANED DATA'!$I:$I,'CLEANED DATA'!$F:$F,'CATEGORY-FINANCIAL ANALYSIS'!A16:A21,'CLEANED DATA'!$G:$G,"Expense")} -> 13946200 | D16: =B16-C16 -> 84372 | E16: =D16/B16 -> 0.0060134398 | F16: =IF(C16>B16,"Unfavorable","Favorable") -> Favorable
A17: Equipment & Maintenance | B17: 14839128 | C17: 14849100 | D17: =C17-B17 -> 9972 | E17: =D17/B17 -> 0.00067200714 | F17: =IF(C17>B17,"Unfavorable","Favorable") -> Unfavorable
A18: Medical Supplies | B18: 14773519 | C18: 14734300 | D18: =C18-B18 -> -39219 | E18: =D18/B18 -> -0.0026546823 | F18: =IF(C18>B18,"Unfavorable","Favorable") -> Favorable
A19: Medicines & Supplies | B19: 15812372 | C19: 15972800 | D19: =C19-B19 -> 160428 | E19: =D19/B19 -> 0.010145726 | F19: =IF(C19>B19,"Unfavorable","Favorable") -> Unfavorable
A20: Staff Costs | B20: 12736074 | C20: 12729400 | D20: =C20-B20 -> -6674 | E20: =D20/B20 -> -0.00052402334 | F20: =IF(C20>B20,"Unfavorable","Favorable") -> Favorable
A21: Utilities | B21: 13086987 | C21: 12940700 | D21: =C21-B21 -> -146287 | E21: =D21/B21 -> -0.01117805 | F21: =IF(C21>B21,"Unfavorable","Favorable") -> Favorable
A24: Favorability logic
A25: Revenue: Actual above Budget = Favorable
A26: Expense: Actual below Budget = Favorable

Sheet UNIT -FINANCIAL ANALYSIS
A1: BUSINESS UNIT-WISE FINANCIAL ANALYSIS
A2: Formula-driven from CLEANED DATA
A3: BUSINESS UNIT | B3: Revenue Budget | C3: Revenue Actual | D3: Revenue Variance | E3: variance | F3: favorable/unfavorable | G3: Expense Budget | H3: Expense Actual | I3: Expense variance | J3: variance | K3: favorable/unfavorable
A4: Diagnostic Services | B4: {=SUMIFS('CLEANED DATA'!$H:$H,'CLEANED DATA'!$E:$E,'UNIT -FINANCIAL ANALYSIS'!A4:A7,'CLEANED DATA'!$G:$G,"Revenue")} -> 38064312 | C4: {=SUMIFS('CLEANED DATA'!$I:$I,'CLEANED DATA'!$E:$E,'UNIT -FINANCIAL ANALYSIS'!A4:A7,'CLEANED DATA'!$G:$G,"Revenue")} -> 37837000 | D4: =C4-B4 -> -227312 | E4: =D4/B4 -> -0.005971788 | F4: =IF(C4>B4,"Favorable","Unfavorable") -> Unfavorable | G4: {=SUMIFS('CLEANED DATA'!$H:$H,'CLEANED DATA'!$E:$E,'UNIT -FINANCIAL ANALYSIS'!A4:A7,'CLEANED DATA'!$G:$G,"Expense")} -> 18390917 | H4: {=SUMIFS('CLEANED DATA'!$I:$I,'CLEANED DATA'!$E:$E,'UNIT -FINANCIAL ANALYSIS'!A4:A7,'CLEANED DATA'!$G:$G,"Expense")} -> 18344200 | I4: =G4-H4 -> 46717 | J4: =I4/G4 -> 0.0025402213 | K4: =IF(H4>G4,"Unfavorable","Favorable") -> Favorable
A5: Emergency Services | B5: 16417217 | C5: 16312100 | D5: =C5-B5 -> -105117 | E5: =D5/B5 -> -0.0064028513 | F5: =IF(C5>B5,"Favorable","Unfavorable") -> Unfavorable | G5: 9326324 | H5: 9358200 | I5: =G5-H5 -> -31876 | J5: =I5/G5 -> -0.0034178525 | K5: =IF(H5>G5,"Unfavorable","Favorable") -> Unfavorable
A6: Inpatient Services | B6: 72440850 | C6: 72256900 | D6: =C6-B6 -> -183950 | E6: =D6/B6 -> -0.0025393131 | F6: =IF(C6>B6,"Favorable","Unfavorable") -> Unfavorable | G6: 33712327 | H6: 33614100 | I6: =G6-H6 -> 98227 | J6: =I6/G6 -> 0.002913682 | K6: =IF(H6>G6,"Unfavorable","Favorable") -> Favorable
A7: Outpatient Services | B7: 40496584 | C7: 40329100 | D7: =C7-B7 -> -167484 | E7: =D7/B7 -> -0.0041357562 | F7: =IF(C7>B7,"Favorable","Unfavorable") -> Unfavorable | G7: 23849084 | H7: 23856000 | I7: =G7-H7 -> -6916 | J7: =I7/G7 -> -0.00028999017 | K7: =IF(H7>G7,"Unfavorable","Favorable") -> Unfavorable
A10: Favorability logic
A11: Revenue: Actual above Budget = Favorable
A12: Expense: Actual below Budget = Favorable

Sheet KPI
J2: KPI | K2: 2025 | L2: FAVORABLE/UNFAVORABLE
J3: TOTAL ACTUAL REVENUE | K3: =SUMIF('CLEANED DATA'!$G:$G,"Revenue",'CLEANED DATA'!$I:$I) -> 166735100 | L3: UNFAVORABLE | O3: Row Labels | P3: Sum of 2025
O4: EXPENSE VARIANCE | P4: 0.0012447664
J5: TOTAL BUDGTED REVENUE | K5: =SUMIF('CLEANED DATA'!$G:$G,"Revenue",'CLEANED DATA'!$H:$H) -> 167418963 | O5: REVENUE VARIANCE | P5: -0.0040847404
O6: TOTAL ACTUAL EXPENSE | P6: 85172500
J7: REVENUE VARIANCE | K7: =(K3-K5)/K5 -> -0.0040847404 | O7: TOTAL ACTUAL REVENUE | P7: 166735100
O8: TOTAL BUDGTED EXPENSE | P8: 85278652
J9: TOTAL ACTUAL EXPENSE | K9: =SUMIF('CLEANED DATA'!$G:$G,"Expense",'CLEANED DATA'!$I:$I) -> 85172500 | L9: FAVORABLE | O9: TOTAL BUDGTED REVENUE | P9: 167418963
O10: (blank)
J11: TOTAL BUDGTED EXPENSE | K11: =SUMIF('CLEANED DATA'!$G:$G,"Expense",'CLEANED DATA'!$H:$H) -> 85278652 | O11: Grand Total | P11: 5.0460521e+08
J13: EXPENSE VARIANCE | K13: =ABS(K9-K11)/K11 -> 0.0012447664 | O13: 85172500
O14: 166735100
O15: 85278652
O16: 167418963
J17: Favorability logic
J18: Revenue: Actual above Budget = Favorable
J19: Expense: Actual below Budget = Favorable

Sheet Sheet1

Sheet PIVOT TABLE
A2: PIVOT BY DEPARTMENT | F2: PIVOT BY BUSINESS UNIT
A3: Row Labels | B3: Sum of Budget Amount | C3: Sum of Actual Amount | F3: Row Labels | G3: Sum of Budget Amount | H3: Sum of Actual Amount
A4: Cardiology | B4: 37825905 | C4: 37764000 | F4: Diagnostic Services | G4: 56455229 | H4: 56181200 | N4: PIVOT MONTHS
A5: Emergency | B5: 25743541 | C5: 25670300 | F5: Emergency Services | G5: 25743541 | H5: 25670300 | N5: Row Labels | O5: Sum of Budget Amount | P5: Sum of Actual Amount
A6: General Medicine | B6: 36862465 | C6: 36966700 | F6: Inpatient Services | G6: 106153177 | H6: 105871000 | N6: Jan | O6: 21535639 | P6: 21611000
A7: Laboratory | B7: 29426943 | C7: 29271000 | F7: Outpatient Services | G7: 64345668 | H7: 64185100 | J7: PIVOT BY QUARTER | N7: Feb | O7: 20377643 | P7: 19929600
A8: Neurology | B8: 34631900 | C8: 34815100 | F8: Grand Total | G8: 252697615 | H8: 251907600 | J8: Row Labels | K8: Sum of Budget Amount | L8: Sum of Actual Amount | N8: Mar | O8: 20805034 | P8: 20582500
A9: Orthopedics | B9: 33695372 | C9: 33291900 | J9: Qtr1 | K9: 62718316 | L9: 62123100 | N9: Apr | O9: 23184081 | P9: 23459500
A10: Pediatrics | B10: 27483203 | C10: 27218400 | J10: Jan | K10: 21535639 | L10: 21611000 | N10: May | O10: 19897007 | P10: 19935000
A11: Radiology | B11: 27028286 | C11: 26910200 | F11: PIVOT BY CATEGORY | J11: Feb | K11: 20377643 | L11: 19929600 | N11: Jun | O11: 19288776 | P11: 19320800
A12: Grand Total | B12: 252697615 | C12: 251907600 | F12: Row Labels | G12: Sum of Budget Amount | H12: Sum of Actual Amount | J12: Mar | K12: 20805034 | L12: 20582500 | N12: Jul | O12: 23330187 | P12: 23226000
F13: Administrative Costs | G13: 14030572 | H13: 13946200 | J13: Qtr2 | K13: 62369864 | L13: 62715300 | N13: Aug | O13: 21516505 | P13: 21499400
A14: PIVOT BY MONTHS | F14: Consultation Services | G14: 27015191 | H14: 26643300 | J14: Apr | K14: 23184081 | L14: 23459500 | N14: Sep | O14: 19231508 | P14: 19222000
A15: Row Labels | B15: Sum of Budget Amount | C15: Sum of Actual Amount | F15: Diagnostic Services | G15: 28450338 | H15: 28248500 | J15: May | K15: 19897007 | L15: 19935000 | N15: Oct | O15: 22646372 | P15: 22610800
A16: Qtr1 | B16: 62718316 | C16: 62123100 | F16: Emergency Services | G16: 26771145 | H16: 26666800 | J16: Jun | K16: 19288776 | L16: 19320800 | N16: Nov | O16: 21674973 | P16: 21456500
A17: Jan | B17: 21535639 | C17: 21611000 | F17: Equipment & Maintenance | G17: 14839128 | H17: 14849100 | J17: Qtr3 | K17: 64078200 | L17: 63947400 | N17: Dec | O17: 19209890 | P17: 19054500
A18: 45658 | B18: 1094492 | C18: 1129500 | F18: Medical Supplies | G18: 14773519 | H18: 14734300 | J18: Jul | K18: 23330187 | L18: 23226000 | N18: Grand Total | O18: 252697615 | P18: 251907600
A19: 45659 | B19: 1132153 | C19: 1096400 | F19: Medicines & Supplies | G19: 15812372 | H19: 15972800 | J19: Aug | K19: 21516505 | L19: 21499400
A20: 45660 | B20: 638888 | C20: 615800 | F20: Pharmacy Services | G20: 27653613 | H20: 27624500 | J20: Sep | K20: 19231508 | L20: 19222000
A21: 45661 | B21: 374779 | C21: 328700 | F21: Staff Costs | G21: 12736074 | H21: 12729400 | J21: Qtr4 | K21: 63531235 | L21: 63121800
A22: 45662 | B22: 501762 | C22: 512200 | F22: Surgical Services | G22: 27681806 | H22: 27397000 | J22: Oct | K22: 22646372 | L22: 22610800
A23: 45663 | B23: 768066 | C23: 798300 | F23: Treatment Services | G23: 29846870 | H23: 30155000 | J23: Nov | K23: 21674973 | L23: 21456500
A24: 45664 | B24: 188700 | C24: 199600 | F24: Utilities | G24: 13086987 | H24: 12940700 | J24: Dec | K24: 19209890 | L24: 19054500
A25: 45665 | B25: 694698 | C25: 725100 | F25: Grand Total | G25: 252697615 | H25: 251907600 | J25: Grand Total | K25: 252697615 | L25: 251907600
A26: 45666 | B26: 286764 | C26: 271100
A27: 45667 | B27: 1385330 | C27: 1461300 | F27: PIVOT BY REGION
A28: 45668 | B28: 419315 | C28: 416700 | F28: Row Labels | G28: Sum of Budget Amount | H28: Sum of Actual Amount
A29: 45669 | B29: 756003 | C29: 705500 | F29: Kerala | G29: 252697615 | H29: 251907600
A30: 45670 | B30: 1376807 | C30: 1348200 | F30: Grand Total | G30: 252697615 | H30: 251907600
A31: 45671 | B31: 580157 | C31: 546100
A32: 45672 | B32: 747066 | C32: 791800
A33: 45673 | B33: 286927 | C33: 278100
A34: 45674 | B34: 311827 | C34: 316200
A35: 45675 | B35: 860896 | C35: 864200
A36: 45676 | B36: 484937 | C36: 463600
A37: 45677 | B37: 583642 | C37: 569100
A38: 45678 | B38: 498239 | C38: 487300
A39: 45679 | B39: 500784 | C39: 510300
A40: 45680 | B40: 880830 | C40: 861300
A41: 45681 | B41: 813573 | C41: 824000
...

Sheet DASHBOARD
M1: #VALUE!
